[2020-04-01 18:16:30,885] {taskinstance.py:655} INFO - Dependencies all met for <TaskInstance: atvt.at_gateway_inference_task 2020-04-01T09:12:00+00:00 [queued]>
[2020-04-01 18:16:31,003] {taskinstance.py:655} INFO - Dependencies all met for <TaskInstance: atvt.at_gateway_inference_task 2020-04-01T09:12:00+00:00 [queued]>
[2020-04-01 18:16:31,003] {taskinstance.py:866} INFO - 
--------------------------------------------------------------------------------
[2020-04-01 18:16:31,003] {taskinstance.py:867} INFO - Starting attempt 1 of 1
[2020-04-01 18:16:31,003] {taskinstance.py:868} INFO - 
--------------------------------------------------------------------------------
[2020-04-01 18:16:31,165] {taskinstance.py:887} INFO - Executing <Task(PythonOperator): at_gateway_inference_task> on 2020-04-01T09:12:00+00:00
[2020-04-01 18:16:31,174] {standard_task_runner.py:53} INFO - Started process 110989 to run task
[2020-04-01 18:16:31,348] {logging_mixin.py:112} INFO - Running %s on host %s <TaskInstance: atvt.at_gateway_inference_task 2020-04-01T09:12:00+00:00 [running]> bi02.com
[2020-04-01 18:16:51,603] {taskinstance.py:1128} ERROR - 'id'
Traceback (most recent call last):
  File "/home/chkimsu/anaconda3/envs/csb2/lib/python3.6/site-packages/pandas/core/indexes/base.py", line 2897, in get_loc
    return self._engine.get_loc(key)
  File "pandas/_libs/index.pyx", line 107, in pandas._libs.index.IndexEngine.get_loc
  File "pandas/_libs/index.pyx", line 131, in pandas._libs.index.IndexEngine.get_loc
  File "pandas/_libs/hashtable_class_helper.pxi", line 1607, in pandas._libs.hashtable.PyObjectHashTable.get_item
  File "pandas/_libs/hashtable_class_helper.pxi", line 1614, in pandas._libs.hashtable.PyObjectHashTable.get_item
KeyError: 'id'

During handling of the above exception, another exception occurred:

Traceback (most recent call last):
  File "/home/chkimsu/anaconda3/envs/csb2/lib/python3.6/site-packages/airflow/models/taskinstance.py", line 966, in _run_raw_task
    result = task_copy.execute(context=context)
  File "/home/chkimsu/anaconda3/envs/csb2/lib/python3.6/site-packages/airflow/operators/python_operator.py", line 113, in execute
    return_value = self.execute_callable()
  File "/home/chkimsu/anaconda3/envs/csb2/lib/python3.6/site-packages/airflow/operators/python_operator.py", line 118, in execute_callable
    return self.python_callable(*self.op_args, **self.op_kwargs)
  File "/data01/CSB/CSB_Jupyter/ATVT/ariflow/dags/atvt_update.py", line 32, in at_gateway_inference_task
    string = data['id'] + '_' + data['description'] + '_' + data['name']
  File "/home/chkimsu/anaconda3/envs/csb2/lib/python3.6/site-packages/pandas/core/frame.py", line 2995, in __getitem__
    indexer = self.columns.get_loc(key)
  File "/home/chkimsu/anaconda3/envs/csb2/lib/python3.6/site-packages/pandas/core/indexes/base.py", line 2899, in get_loc
    return self._engine.get_loc(self._maybe_cast_indexer(key))
  File "pandas/_libs/index.pyx", line 107, in pandas._libs.index.IndexEngine.get_loc
  File "pandas/_libs/index.pyx", line 131, in pandas._libs.index.IndexEngine.get_loc
  File "pandas/_libs/hashtable_class_helper.pxi", line 1607, in pandas._libs.hashtable.PyObjectHashTable.get_item
  File "pandas/_libs/hashtable_class_helper.pxi", line 1614, in pandas._libs.hashtable.PyObjectHashTable.get_item
KeyError: 'id'
[2020-04-01 18:16:51,608] {taskinstance.py:1185} INFO - Marking task as FAILED.dag_id=atvt, task_id=at_gateway_inference_task, execution_date=20200401T091200, start_date=20200401T091630, end_date=20200401T091651
[2020-04-01 18:16:56,783] {logging_mixin.py:112} INFO - [2020-04-01 18:16:56,782] {local_task_job.py:103} INFO - Task exited with return code 1
