[2020-04-17 13:59:08,663] {taskinstance.py:655} INFO - Dependencies all met for <TaskInstance: atvt_inferencing.at_gateway_inference_task 2020-04-17T04:56:00+00:00 [queued]>
[2020-04-17 13:59:08,669] {taskinstance.py:655} INFO - Dependencies all met for <TaskInstance: atvt_inferencing.at_gateway_inference_task 2020-04-17T04:56:00+00:00 [queued]>
[2020-04-17 13:59:08,670] {taskinstance.py:866} INFO - 
--------------------------------------------------------------------------------
[2020-04-17 13:59:08,670] {taskinstance.py:867} INFO - Starting attempt 1 of 1
[2020-04-17 13:59:08,670] {taskinstance.py:868} INFO - 
--------------------------------------------------------------------------------
[2020-04-17 13:59:08,746] {taskinstance.py:887} INFO - Executing <Task(PythonOperator): at_gateway_inference_task> on 2020-04-17T04:56:00+00:00
[2020-04-17 13:59:08,757] {standard_task_runner.py:53} INFO - Started process 28781 to run task
[2020-04-17 13:59:08,910] {logging_mixin.py:112} INFO - Running %s on host %s <TaskInstance: atvt_inferencing.at_gateway_inference_task 2020-04-17T04:56:00+00:00 [running]> bi02.com
[2020-04-17 13:59:39,150] {taskinstance.py:1128} ERROR - (2003, "Can't connect to MySQL server on '192.168.21.6' (timed out)")
Traceback (most recent call last):
  File "/home/chkimsu/anaconda3/envs/csb2/lib/python3.6/site-packages/pymysql/connections.py", line 583, in connect
    **kwargs)
  File "/home/chkimsu/anaconda3/envs/csb2/lib/python3.6/socket.py", line 724, in create_connection
    raise err
  File "/home/chkimsu/anaconda3/envs/csb2/lib/python3.6/socket.py", line 713, in create_connection
    sock.connect(sa)
socket.timeout: timed out

During handling of the above exception, another exception occurred:

Traceback (most recent call last):
  File "/home/chkimsu/anaconda3/envs/csb2/lib/python3.6/site-packages/airflow/models/taskinstance.py", line 966, in _run_raw_task
    result = task_copy.execute(context=context)
  File "/home/chkimsu/anaconda3/envs/csb2/lib/python3.6/site-packages/airflow/operators/python_operator.py", line 113, in execute
    return_value = self.execute_callable()
  File "/home/chkimsu/anaconda3/envs/csb2/lib/python3.6/site-packages/airflow/operators/python_operator.py", line 118, in execute_callable
    return self.python_callable(*self.op_args, **self.op_kwargs)
  File "/data01/CSB/CSB_Jupyter/ATVT/ariflow/dags/.ipynb_checkpoints/Inferencing_airflow-module-checkpoint.py", line 149, in at_gateway_inference_task
    data = db_connect()
  File "/data01/CSB/CSB_Jupyter/ATVT/ariflow/dags/.ipynb_checkpoints/Inferencing_airflow-module-checkpoint.py", line 45, in db_connect
    cursorclass=pymysql.cursors.DictCursor)
  File "/home/chkimsu/anaconda3/envs/csb2/lib/python3.6/site-packages/pymysql/__init__.py", line 94, in Connect
    return Connection(*args, **kwargs)
  File "/home/chkimsu/anaconda3/envs/csb2/lib/python3.6/site-packages/pymysql/connections.py", line 325, in __init__
    self.connect()
  File "/home/chkimsu/anaconda3/envs/csb2/lib/python3.6/site-packages/pymysql/connections.py", line 630, in connect
    raise exc
pymysql.err.OperationalError: (2003, "Can't connect to MySQL server on '192.168.21.6' (timed out)")
[2020-04-17 13:59:39,152] {taskinstance.py:1185} INFO - Marking task as FAILED.dag_id=atvt_inferencing, task_id=at_gateway_inference_task, execution_date=20200417T045600, start_date=20200417T045908, end_date=20200417T045939
[2020-04-17 13:59:40,430] {logging_mixin.py:112} INFO - [2020-04-17 13:59:40,430] {local_task_job.py:103} INFO - Task exited with return code 1
