[2020-04-01 18:17:50,417] {taskinstance.py:655} INFO - Dependencies all met for <TaskInstance: atvt.at_gateway_inference_task 2020-04-01T09:14:00+00:00 [queued]>
[2020-04-01 18:17:50,531] {taskinstance.py:655} INFO - Dependencies all met for <TaskInstance: atvt.at_gateway_inference_task 2020-04-01T09:14:00+00:00 [queued]>
[2020-04-01 18:17:50,532] {taskinstance.py:866} INFO - 
--------------------------------------------------------------------------------
[2020-04-01 18:17:50,532] {taskinstance.py:867} INFO - Starting attempt 1 of 1
[2020-04-01 18:17:50,532] {taskinstance.py:868} INFO - 
--------------------------------------------------------------------------------
[2020-04-01 18:17:50,674] {taskinstance.py:887} INFO - Executing <Task(PythonOperator): at_gateway_inference_task> on 2020-04-01T09:14:00+00:00
[2020-04-01 18:17:50,682] {standard_task_runner.py:53} INFO - Started process 111194 to run task
[2020-04-01 18:17:50,878] {logging_mixin.py:112} INFO - Running %s on host %s <TaskInstance: atvt.at_gateway_inference_task 2020-04-01T09:14:00+00:00 [running]> bi02.com
[2020-04-01 18:18:10,620] {taskinstance.py:1128} ERROR - 'id'
Traceback (most recent call last):
  File "/home/chkimsu/anaconda3/envs/csb2/lib/python3.6/site-packages/pandas/core/indexes/base.py", line 2897, in get_loc
    return self._engine.get_loc(key)
  File "pandas/_libs/index.pyx", line 107, in pandas._libs.index.IndexEngine.get_loc
  File "pandas/_libs/index.pyx", line 131, in pandas._libs.index.IndexEngine.get_loc
  File "pandas/_libs/hashtable_class_helper.pxi", line 1607, in pandas._libs.hashtable.PyObjectHashTable.get_item
  File "pandas/_libs/hashtable_class_helper.pxi", line 1614, in pandas._libs.hashtable.PyObjectHashTable.get_item
KeyError: 'id'

During handling of the above exception, another exception occurred:

Traceback (most recent call last):
  File "/home/chkimsu/anaconda3/envs/csb2/lib/python3.6/site-packages/airflow/models/taskinstance.py", line 966, in _run_raw_task
    result = task_copy.execute(context=context)
  File "/home/chkimsu/anaconda3/envs/csb2/lib/python3.6/site-packages/airflow/operators/python_operator.py", line 113, in execute
    return_value = self.execute_callable()
  File "/home/chkimsu/anaconda3/envs/csb2/lib/python3.6/site-packages/airflow/operators/python_operator.py", line 118, in execute_callable
    return self.python_callable(*self.op_args, **self.op_kwargs)
  File "/data01/CSB/CSB_Jupyter/ATVT/ariflow/dags/atvt_update.py", line 32, in at_gateway_inference_task
    string = data['id'] + '_' + data['description'] + '_' + data['name']
  File "/home/chkimsu/anaconda3/envs/csb2/lib/python3.6/site-packages/pandas/core/frame.py", line 2995, in __getitem__
    indexer = self.columns.get_loc(key)
  File "/home/chkimsu/anaconda3/envs/csb2/lib/python3.6/site-packages/pandas/core/indexes/base.py", line 2899, in get_loc
    return self._engine.get_loc(self._maybe_cast_indexer(key))
  File "pandas/_libs/index.pyx", line 107, in pandas._libs.index.IndexEngine.get_loc
  File "pandas/_libs/index.pyx", line 131, in pandas._libs.index.IndexEngine.get_loc
  File "pandas/_libs/hashtable_class_helper.pxi", line 1607, in pandas._libs.hashtable.PyObjectHashTable.get_item
  File "pandas/_libs/hashtable_class_helper.pxi", line 1614, in pandas._libs.hashtable.PyObjectHashTable.get_item
KeyError: 'id'
[2020-04-01 18:18:10,624] {taskinstance.py:1185} INFO - Marking task as FAILED.dag_id=atvt, task_id=at_gateway_inference_task, execution_date=20200401T091400, start_date=20200401T091750, end_date=20200401T091810
[2020-04-01 18:18:13,071] {logging_mixin.py:112} INFO - [2020-04-01 18:18:13,070] {local_task_job.py:167} WARNING - State of this instance has been externally set to failed. Taking the poison pill.
[2020-04-01 18:18:13,082] {helpers.py:322} INFO - Sending Signals.SIGTERM to GPID 111194
[2020-04-01 18:18:13,134] {helpers.py:288} INFO - Process psutil.Process(pid=111194, status='terminated') (111194) terminated with exit code 1
[2020-04-01 18:18:18,073] {logging_mixin.py:112} INFO - [2020-04-01 18:18:18,073] {local_task_job.py:103} INFO - Task exited with return code 1
